Workbook

Sheet Instrucciones
A1: Cómo usar esta plantilla
A3: 1. Equipos
A4: Escribe el nombre de cada equipo inscrito en la hoja "Equipos", columna A. Borra la fila de ejemplo cuando tengas tus equipos reales.
A6: 2. Partidos
A7: Cada vez que se juegue un partido, agrega una fila en la hoja "Partidos": fecha, jornada, equipo local, goles del local, equipo visitante, goles del visitante.
A9: 3. Posiciones
A10: No toques nada aquí: la hoja "Posiciones" se recalcula y se ordena sola (PJ, PG, PE, PP, GF, GC, diferencia de gol y puntos) apenas registras un partido. La tabla ya sale ordenada de 1° a último — nunca uses Datos > Ordenar rango sobre ella, porque puede desordenar las fórmulas.
A12: 4. Desempates
A13: El orden se calcula por Puntos, luego Diferencia de gol, luego Goles a favor. Si dos equipos quedan exactamente iguales en todo, se ordenan por el orden en que los escribiste en la hoja Equipos.
A15: 5. Hoja Detalle
A16: Es un cálculo interno que separa cada partido en dos filas (una por equipo). No la edites, pero no la borres: de ahí toma los datos la hoja Posiciones.
A19: Para usarla en Google Sheets: sube este archivo .xlsx a Google Drive y ábrelo — Sheets lo convierte automáticamente y las fórmulas siguen funcionando igual.

Sheet Equipos
A1: Equipo
A2: X-GRAPHICS
A3: GRAFICAJAS
A4: ADH
A5: LEONARD
A6: MACULA DEL MAL
A7: MULTIAVISOS DE LA 12

Sheet Partidos
A1: Fecha | B1: Jornada | C1: Equipo Local | D1: Goles Local | E1: Equipo Visitante | F1: Goles Visitante
A2: 2026-08-15 | B2: 1 | C2: LEONARD | D2: 5 | E2: GRAFICAJAS | F2: 2
A3: 2026-08-15 | B3: 1 | C3: MACULA DEL MAL | D3: 4 | E3: MULTIAVISOS DE LA 12 | F3: 4
A4: 2026-08-15 | B4: 1 | C4: ADH | D4: 6 | E4: X-GRAPHICS | F4: 1

Sheet Detalle
A1: Equipo | B1: GF | C1: GC | D1: Resultado | E1: Puntos
A2: =IF(Partidos!C2="","",Partidos!C2) -> LEONARD | B2: =IF(Partidos!C2="","",Partidos!D2) -> 5 | C2: =IF(Partidos!C2="","",Partidos!F2) -> 2 | D2: =IF(Partidos!C2="","",IF(Partidos!D2>Partidos!F2,"G",IF(Partidos!D2=Partidos!F2,"E","P"))) -> G | E2: =IF(Partidos!C2="","",IF(D2="G",3,IF(D2="E",1,0))) -> 3
A3: =IF(Partidos!E2="","",Partidos!E2) -> GRAFICAJAS | B3: =IF(Partidos!E2="","",Partidos!F2) -> 2 | C3: =IF(Partidos!E2="","",Partidos!D2) -> 5 | D3: =IF(Partidos!E2="","",IF(Partidos!F2>Partidos!D2,"G",IF(Partidos!F2=Partidos!D2,"E","P"))) -> P | E3: =IF(Partidos!E2="","",IF(D3="G",3,IF(D3="E",1,0))) -> 0
A4: =IF(Partidos!C3="","",Partidos!C3) -> MACULA DEL MAL | B4: =IF(Partidos!C3="","",Partidos!D3) -> 4 | C4: =IF(Partidos!C3="","",Partidos!F3) -> 4 | D4: =IF(Partidos!C3="","",IF(Partidos!D3>Partidos!F3,"G",IF(Partidos!D3=Partidos!F3,"E","P"))) -> E | E4: =IF(Partidos!C3="","",IF(D4="G",3,IF(D4="E",1,0))) -> 1
A5: =IF(Partidos!E3="","",Partidos!E3) -> MULTIAVISOS DE LA 12 | B5: =IF(Partidos!E3="","",Partidos!F3) -> 4 | C5: =IF(Partidos!E3="","",Partidos!D3) -> 4 | D5: =IF(Partidos!E3="","",IF(Partidos!F3>Partidos!D3,"G",IF(Partidos!F3=Partidos!D3,"E","P"))) -> E | E5: =IF(Partidos!E3="","",IF(D5="G",3,IF(D5="E",1,0))) -> 1
A6: =IF(Partidos!C4="","",Partidos!C4) -> ADH | B6: =IF(Partidos!C4="","",Partidos!D4) -> 6 | C6: =IF(Partidos!C4="","",Partidos!F4) -> 1 | D6: =IF(Partidos!C4="","",IF(Partidos!D4>Partidos!F4,"G",IF(Partidos!D4=Partidos!F4,"E","P"))) -> G | E6: =IF(Partidos!C4="","",IF(D6="G",3,IF(D6="E",1,0))) -> 3
A7: =IF(Partidos!E4="","",Partidos!E4) -> X-GRAPHICS | B7: =IF(Partidos!E4="","",Partidos!F4) -> 1 | C7: =IF(Partidos!E4="","",Partidos!D4) -> 6 | D7: =IF(Partidos!E4="","",IF(Partidos!F4>Partidos!D4,"G",IF(Partidos!F4=Partidos!D4,"E","P"))) -> P | E7: =IF(Partidos!E4="","",IF(D7="G",3,IF(D7="E",1,0))) -> 0
A8: =IF(Partidos!C5="","",Partidos!C5) | B8: =IF(Partidos!C5="","",Partidos!D5) | C8: =IF(Partidos!C5="","",Partidos!F5) | D8: =IF(Partidos!C5="","",IF(Partidos!D5>Partidos!F5,"G",IF(Partidos!D5=Partidos!F5,"E","P"))) | E8: =IF(Partidos!C5="","",IF(D8="G",3,IF(D8="E",1,0)))
A9: =IF(Partidos!E5="","",Partidos!E5) | B9: =IF(Partidos!E5="","",Partidos!F5) | C9: =IF(Partidos!E5="","",Partidos!D5) | D9: =IF(Partidos!E5="","",IF(Partidos!F5>Partidos!D5,"G",IF(Partidos!F5=Partidos!D5,"E","P"))) | E9: =IF(Partidos!E5="","",IF(D9="G",3,IF(D9="E",1,0)))
A10: =IF(Partidos!C6="","",Partidos!C6) | B10: =IF(Partidos!C6="","",Partidos!D6) | C10: =IF(Partidos!C6="","",Partidos!F6) | D10: =IF(Partidos!C6="","",IF(Partidos!D6>Partidos!F6,"G",IF(Partidos!D6=Partidos!F6,"E","P"))) | E10: =IF(Partidos!C6="","",IF(D10="G",3,IF(D10="E",1,0)))
A11: =IF(Partidos!E6="","",Partidos!E6) | B11: =IF(Partidos!E6="","",Partidos!F6) | C11: =IF(Partidos!E6="","",Partidos!D6) | D11: =IF(Partidos!E6="","",IF(Partidos!F6>Partidos!D6,"G",IF(Partidos!F6=Partidos!D6,"E","P"))) | E11: =IF(Partidos!E6="","",IF(D11="G",3,IF(D11="E",1,0)))
A12: =IF(Partidos!C7="","",Partidos!C7) | B12: =IF(Partidos!C7="","",Partidos!D7) | C12: =IF(Partidos!C7="","",Partidos!F7) | D12: =IF(Partidos!C7="","",IF(Partidos!D7>Partidos!F7,"G",IF(Partidos!D7=Partidos!F7,"E","P"))) | E12: =IF(Partidos!C7="","",IF(D12="G",3,IF(D12="E",1,0)))
A13: =IF(Partidos!E7="","",Partidos!E7) | B13: =IF(Partidos!E7="","",Partidos!F7) | C13: =IF(Partidos!E7="","",Partidos!D7) | D13: =IF(Partidos!E7="","",IF(Partidos!F7>Partidos!D7,"G",IF(Partidos!F7=Partidos!D7,"E","P"))) | E13: =IF(Partidos!E7="","",IF(D13="G",3,IF(D13="E",1,0)))
A14: =IF(Partidos!C8="","",Partidos!C8) | B14: =IF(Partidos!C8="","",Partidos!D8) | C14: =IF(Partidos!C8="","",Partidos!F8) | D14: =IF(Partidos!C8="","",IF(Partidos!D8>Partidos!F8,"G",IF(Partidos!D8=Partidos!F8,"E","P"))) | E14: =IF(Partidos!C8="","",IF(D14="G",3,IF(D14="E",1,0)))
A15: =IF(Partidos!E8="","",Partidos!E8) | B15: =IF(Partidos!E8="","",Partidos!F8) | C15: =IF(Partidos!E8="","",Partidos!D8) | D15: =IF(Partidos!E8="","",IF(Partidos!F8>Partidos!D8,"G",IF(Partidos!F8=Partidos!D8,"E","P"))) | E15: =IF(Partidos!E8="","",IF(D15="G",3,IF(D15="E",1,0)))
A16: =IF(Partidos!C9="","",Partidos!C9) | B16: =IF(Partidos!C9="","",Partidos!D9) | C16: =IF(Partidos!C9="","",Partidos!F9) | D16: =IF(Partidos!C9="","",IF(Partidos!D9>Partidos!F9,"G",IF(Partidos!D9=Partidos!F9,"E","P"))) | E16: =IF(Partidos!C9="","",IF(D16="G",3,IF(D16="E",1,0)))
A17: =IF(Partidos!E9="","",Partidos!E9) | B17: =IF(Partidos!E9="","",Partidos!F9) | C17: =IF(Partidos!E9="","",Partidos!D9) | D17: =IF(Partidos!E9="","",IF(Partidos!F9>Partidos!D9,"G",IF(Partidos!F9=Partidos!D9,"E","P"))) | E17: =IF(Partidos!E9="","",IF(D17="G",3,IF(D17="E",1,0)))
A18: =IF(Partidos!C10="","",Partidos!C10) | B18: =IF(Partidos!C10="","",Partidos!D10) | C18: =IF(Partidos!C10="","",Partidos!F10) | D18: =IF(Partidos!C10="","",IF(Partidos!D10>Partidos!F10,"G",IF(Partidos!D10=Partidos!F10,"E","P"))) | E18: =IF(Partidos!C10="","",IF(D18="G",3,IF(D18="E",1,0)))
A19: =IF(Partidos!E10="","",Partidos!E10) | B19: =IF(Partidos!E10="","",Partidos!F10) | C19: =IF(Partidos!E10="","",Partidos!D10) | D19: =IF(Partidos!E10="","",IF(Partidos!F10>Partidos!D10,"G",IF(Partidos!F10=Partidos!D10,"E","P"))) | E19: =IF(Partidos!E10="","",IF(D19="G",3,IF(D19="E",1,0)))
A20: =IF(Partidos!C11="","",Partidos!C11) | B20: =IF(Partidos!C11="","",Partidos!D11) | C20: =IF(Partidos!C11="","",Partidos!F11) | D20: =IF(Partidos!C11="","",IF(Partidos!D11>Partidos!F11,"G",IF(Partidos!D11=Partidos!F11,"E","P"))) | E20: =IF(Partidos!C11="","",IF(D20="G",3,IF(D20="E",1,0)))
A21: =IF(Partidos!E11="","",Partidos!E11) | B21: =IF(Partidos!E11="","",Partidos!F11) | C21: =IF(Partidos!E11="","",Partidos!D11) | D21: =IF(Partidos!E11="","",IF(Partidos!F11>Partidos!D11,"G",IF(Partidos!F11=Partidos!D11,"E","P"))) | E21: =IF(Partidos!E11="","",IF(D21="G",3,IF(D21="E",1,0)))
A22: =IF(Partidos!C12="","",Partidos!C12) | B22: =IF(Partidos!C12="","",Partidos!D12) | C22: =IF(Partidos!C12="","",Partidos!F12) | D22: =IF(Partidos!C12="","",IF(Partidos!D12>Partidos!F12,"G",IF(Partidos!D12=Partidos!F12,"E","P"))) | E22: =IF(Partidos!C12="","",IF(D22="G",3,IF(D22="E",1,0)))
A23: =IF(Partidos!E12="","",Partidos!E12) | B23: =IF(Partidos!E12="","",Partidos!F12) | C23: =IF(Partidos!E12="","",Partidos!D12) | D23: =IF(Partidos!E12="","",IF(Partidos!F12>Partidos!D12,"G",IF(Partidos!F12=Partidos!D12,"E","P"))) | E23: =IF(Partidos!E12="","",IF(D23="G",3,IF(D23="E",1,0)))
A24: =IF(Partidos!C13="","",Partidos!C13) | B24: =IF(Partidos!C13="","",Partidos!D13) | C24: =IF(Partidos!C13="","",Partidos!F13) | D24: =IF(Partidos!C13="","",IF(Partidos!D13>Partidos!F13,"G",IF(Partidos!D13=Partidos!F13,"E","P"))) | E24: =IF(Partidos!C13="","",IF(D24="G",3,IF(D24="E",1,0)))
A25: =IF(Partidos!E13="","",Partidos!E13) | B25: =IF(Partidos!E13="","",Partidos!F13) | C25: =IF(Partidos!E13="","",Partidos!D13) | D25: =IF(Partidos!E13="","",IF(Partidos!F13>Partidos!D13,"G",IF(Partidos!F13=Partidos!D13,"E","P"))) | E25: =IF(Partidos!E13="","",IF(D25="G",3,IF(D25="E",1,0)))
A26: =IF(Partidos!C14="","",Partidos!C14) | B26: =IF(Partidos!C14="","",Partidos!D14) | C26: =IF(Partidos!C14="","",Partidos!F14) | D26: =IF(Partidos!C14="","",IF(Partidos!D14>Partidos!F14,"G",IF(Partidos!D14=Partidos!F14,"E","P"))) | E26: =IF(Partidos!C14="","",IF(D26="G",3,IF(D26="E",1,0)))
A27: =IF(Partidos!E14="","",Partidos!E14) | B27: =IF(Partidos!E14="","",Partidos!F14) | C27: =IF(Partidos!E14="","",Partidos!D14) | D27: =IF(Partidos!E14="","",IF(Partidos!F14>Partidos!D14,"G",IF(Partidos!F14=Partidos!D14,"E","P"))) | E27: =IF(Partidos!E14="","",IF(D27="G",3,IF(D27="E",1,0)))
A28: =IF(Partidos!C15="","",Partidos!C15) | B28: =IF(Partidos!C15="","",Partidos!D15) | C28: =IF(Partidos!C15="","",Partidos!F15) | D28: =IF(Partidos!C15="","",IF(Partidos!D15>Partidos!F15,"G",IF(Partidos!D15=Partidos!F15,"E","P"))) | E28: =IF(Partidos!C15="","",IF(D28="G",3,IF(D28="E",1,0)))
A29: =IF(Partidos!E15="","",Partidos!E15) | B29: =IF(Partidos!E15="","",Partidos!F15) | C29: =IF(Partidos!E15="","",Partidos!D15) | D29: =IF(Partidos!E15="","",IF(Partidos!F15>Partidos!D15,"G",IF(Partidos!F15=Partidos!D15,"E","P"))) | E29: =IF(Partidos!E15="","",IF(D29="G",3,IF(D29="E",1,0)))
A30: =IF(Partidos!C16="","",Partidos!C16) | B30: =IF(Partidos!C16="","",Partidos!D16) | C30: =IF(Partidos!C16="","",Partidos!F16) | D30: =IF(Partidos!C16="","",IF(Partidos!D16>Partidos!F16,"G",IF(Partidos!D16=Partidos!F16,"E","P"))) | E30: =IF(Partidos!C16="","",IF(D30="G",3,IF(D30="E",1,0)))
A31: =IF(Partidos!E16="","",Partidos!E16) | B31: =IF(Partidos!E16="","",Partidos!F16) | C31: =IF(Partidos!E16="","",Partidos!D16) | D31: =IF(Partidos!E16="","",IF(Partidos!F16>Partidos!D16,"G",IF(Partidos!F16=Partidos!D16,"E","P"))) | E31: =IF(Partidos!E16="","",IF(D31="G",3,IF(D31="E",1,0)))
A32: =IF(Partidos!C17="","",Partidos!C17) | B32: =IF(Partidos!C17="","",Partidos!D17) | C32: =IF(Partidos!C17="","",Partidos!F17) | D32: =IF(Partidos!C17="","",IF(Partidos!D17>Partidos!F17,"G",IF(Partidos!D17=Partidos!F17,"E","P"))) | E32: =IF(Partidos!C17="","",IF(D32="G",3,IF(D32="E",1,0)))
A33: =IF(Partidos!E17="","",Partidos!E17) | B33: =IF(Partidos!E17="","",Partidos!F17) | C33: =IF(Partidos!E17="","",Partidos!D17) | D33: =IF(Partidos!E17="","",IF(Partidos!F17>Partidos!D17,"G",IF(Partidos!F17=Partidos!D17,"E","P"))) | E33: =IF(Partidos!E17="","",IF(D33="G",3,IF(D33="E",1,0)))
A34: =IF(Partidos!C18="","",Partidos!C18) | B34: =IF(Partidos!C18="","",Partidos!D18) | C34: =IF(Partidos!C18="","",Partidos!F18) | D34: =IF(Partidos!C18="","",IF(Partidos!D18>Partidos!F18,"G",IF(Partidos!D18=Partidos!F18,"E","P"))) | E34: =IF(Partidos!C18="","",IF(D34="G",3,IF(D34="E",1,0)))
A35: =IF(Partidos!E18="","",Partidos!E18) | B35: =IF(Partidos!E18="","",Partidos!F18) | C35: =IF(Partidos!E18="","",Partidos!D18) | D35: =IF(Partidos!E18="","",IF(Partidos!F18>Partidos!D18,"G",IF(Partidos!F18=Partidos!D18,"E","P"))) | E35: =IF(Partidos!E18="","",IF(D35="G",3,IF(D35="E",1,0)))
A36: =IF(Partidos!C19="","",Partidos!C19) | B36: =IF(Partidos!C19="","",Partidos!D19) | C36: =IF(Partidos!C19="","",Partidos!F19) | D36: =IF(Partidos!C19="","",IF(Partidos!D19>Partidos!F19,"G",IF(Partidos!D19=Partidos!F19,"E","P"))) | E36: =IF(Partidos!C19="","",IF(D36="G",3,IF(D36="E",1,0)))
A37: =IF(Partidos!E19="","",Partidos!E19) | B37: =IF(Partidos!E19="","",Partidos!F19) | C37: =IF(Partidos!E19="","",Partidos!D19) | D37: =IF(Partidos!E19="","",IF(Partidos!F19>Partidos!D19,"G",IF(Partidos!F19=Partidos!D19,"E","P"))) | E37: =IF(Partidos!E19="","",IF(D37="G",3,IF(D37="E",1,0)))
A38: =IF(Partidos!C20="","",Partidos!C20) | B38: =IF(Partidos!C20="","",Partidos!D20) | C38: =IF(Partidos!C20="","",Partidos!F20) | D38: =IF(Partidos!C20="","",IF(Partidos!D20>Partidos!F20,"G",IF(Partidos!D20=Partidos!F20,"E","P"))) | E38: =IF(Partidos!C20="","",IF(D38="G",3,IF(D38="E",1,0)))
A39: =IF(Partidos!E20="","",Partidos!E20) | B39: =IF(Partidos!E20="","",Partidos!F20) | C39: =IF(Partidos!E20="","",Partidos!D20) | D39: =IF(Partidos!E20="","",IF(Partidos!F20>Partidos!D20,"G",IF(Partidos!F20=Partidos!D20,"E","P"))) | E39: =IF(Partidos!E20="","",IF(D39="G",3,IF(D39="E",1,0)))
A40: =IF(Partidos!C21="","",Partidos!C21) | B40: =IF(Partidos!C21="","",Partidos!D21) | C40: =IF(Partidos!C21="","",Partidos!F21) | D40: =IF(Partidos!C21="","",IF(Partidos!D21>Partidos!F21,"G",IF(Partidos!D21=Partidos!F21,"E","P"))) | E40: =IF(Partidos!C21="","",IF(D40="G",3,IF(D40="E",1,0)))
...

Sheet Posiciones
A1: Equipo | B1: PJ | C1: PG | D1: PE | E1: PP | F1: GF | G1: GC | H1: DG | I1: PTS | J1: Orden | K1: OrdenÚnico | L1: Pos | N1: Pos | O1: Equipo | P1: PJ | Q1: PG | R1: PE | S1: PP | T1: GF | U1: GC | V1: DG | W1: PTS
A2: =IF(Equipos!A2="","",Equipos!A2) -> X-GRAPHICS | B2: =IF($A2="","",COUNTIF(Detalle!$A$2:$A$201,$A2)) -> 1 | C2: =IF($A2="","",COUNTIFS(Detalle!$A$2:$A$201,$A2,Detalle!$D$2:$D$201,"G")) -> 0 | D2: =IF($A2="","",COUNTIFS(Detalle!$A$2:$A$201,$A2,Detalle!$D$2:$D$201,"E")) -> 0 | E2: =IF($A2="","",COUNTIFS(Detalle!$A$2:$A$201,$A2,Detalle!$D$2:$D$201,"P")) -> 1 | F2: =IF($A2="","",SUMIFS(Detalle!$B$2:$B$201,Detalle!$A$2:$A$201,$A2)) -> 1 | G2: =IF($A2="","",SUMIFS(Detalle!$C$2:$C$201,Detalle!$A$2:$A$201,$A2)) -> 6 | H2: =IF($A2="","",F2-G2) -> -5 | I2: =IF($A2="","",SUMIFS(Detalle!$E$2:$E$201,Detalle!$A$2:$A$201,$A2)) -> 0 | J2: =IF($A2="","",I2*1000+H2*10+F2) -> -49 | K2: =IF($A2="","",J2-ROW()/100000) -> -49.00002 | L2: =IF($A2="","",RANK(K2,$K$2:$K$18,0)) -> 6 | N2: =IF((ROW()-1)<=COUNTA(Equipos!$A$2:$A$18),ROW()-1,"") -> 1 | O2: =IFERROR(INDEX($A$2:$A$18,MATCH($N2,$L$2:$L$18,0)),"") -> ADH | P2: =IFERROR(INDEX($B$2:$B$18,MATCH($N2,$L$2:$L$18,0)),"") -> 1 | Q2: =IFERROR(INDEX($C$2:$C$18,MATCH($N2,$L$2:$L$18,0)),"") -> 1 | R2: =IFERROR(INDEX($D$2:$D$18,MATCH($N2,$L$2:$L$18,0)),"") -> 0 | S2: =IFERROR(INDEX($E$2:$E$18,MATCH($N2,$L$2:$L$18,0)),"") -> 0 | T2: =IFERROR(INDEX($F$2:$F$18,MATCH($N2,$L$2:$L$18,0)),"") -> 6 | U2: =IFERROR(INDEX($G$2:$G$18,MATCH($N2,$L$2:$L$18,0)),"") -> 1 | V2: =IFERROR(INDEX($H$2:$H$18,MATCH($N2,$L$2:$L$18,0)),"") -> 5 | W2: =IFERROR(INDEX($I$2:$I$18,MATCH($N2,$L$2:$L$18,0)),"") -> 3
A3: =IF(Equipos!A3="","",Equipos!A3) -> GRAFICAJAS | B3: =IF($A3="","",COUNTIF(Detalle!$A$2:$A$201,$A3)) -> 1 | C3: =IF($A3="","",COUNTIFS(Detalle!$A$2:$A$201,$A3,Detalle!$D$2:$D$201,"G")) -> 0 | D3: =IF($A3="","",COUNTIFS(Detalle!$A$2:$A$201,$A3,Detalle!$D$2:$D$201,"E")) -> 0 | E3: =IF($A3="","",COUNTIFS(Detalle!$A$2:$A$201,$A3,Detalle!$D$2:$D$201,"P")) -> 1 | F3: =IF($A3="","",SUMIFS(Detalle!$B$2:$B$201,Detalle!$A$2:$A$201,$A3)) -> 2 | G3: =IF($A3="","",SUMIFS(Detalle!$C$2:$C$201,Detalle!$A$2:$A$201,$A3)) -> 5 | H3: =IF($A3="","",F3-G3) -> -3 | I3: =IF($A3="","",SUMIFS(Detalle!$E$2:$E$201,Detalle!$A$2:$A$201,$A3)) -> 0 | J3: =IF($A3="","",I3*1000+H3*10+F3) -> -28 | K3: =IF($A3="","",J3-ROW()/100000) -> -28.00003 | L3: =IF($A3="","",RANK(K3,$K$2:$K$18,0)) -> 5 | N3: =IF((ROW()-1)<=COUNTA(Equipos!$A$2:$A$18),ROW()-1,"") -> 2 | O3: =IFERROR(INDEX($A$2:$A$18,MATCH($N3,$L$2:$L$18,0)),"") -> LEONARD | P3: =IFERROR(INDEX($B$2:$B$18,MATCH($N3,$L$2:$L$18,0)),"") -> 1 | Q3: =IFERROR(INDEX($C$2:$C$18,MATCH($N3,$L$2:$L$18,0)),"") -> 1 | R3: =IFERROR(INDEX($D$2:$D$18,MATCH($N3,$L$2:$L$18,0)),"") -> 0 | S3: =IFERROR(INDEX($E$2:$E$18,MATCH($N3,$L$2:$L$18,0)),"") -> 0 | T3: =IFERROR(INDEX($F$2:$F$18,MATCH($N3,$L$2:$L$18,0)),"") -> 5 | U3: =IFERROR(INDEX($G$2:$G$18,MATCH($N3,$L$2:$L$18,0)),"") -> 2 | V3: =IFERROR(INDEX($H$2:$H$18,MATCH($N3,$L$2:$L$18,0)),"") -> 3 | W3: =IFERROR(INDEX($I$2:$I$18,MATCH($N3,$L$2:$L$18,0)),"") -> 3
A4: =IF(Equipos!A4="","",Equipos!A4) -> ADH | B4: =IF($A4="","",COUNTIF(Detalle!$A$2:$A$201,$A4)) -> 1 | C4: =IF($A4="","",COUNTIFS(Detalle!$A$2:$A$201,$A4,Detalle!$D$2:$D$201,"G")) -> 1 | D4: =IF($A4="","",COUNTIFS(Detalle!$A$2:$A$201,$A4,Detalle!$D$2:$D$201,"E")) -> 0 | E4: =IF($A4="","",COUNTIFS(Detalle!$A$2:$A$201,$A4,Detalle!$D$2:$D$201,"P")) -> 0 | F4: =IF($A4="","",SUMIFS(Detalle!$B$2:$B$201,Detalle!$A$2:$A$201,$A4)) -> 6 | G4: =IF($A4="","",SUMIFS(Detalle!$C$2:$C$201,Detalle!$A$2:$A$201,$A4)) -> 1 | H4: =IF($A4="","",F4-G4) -> 5 | I4: =IF($A4="","",SUMIFS(Detalle!$E$2:$E$201,Detalle!$A$2:$A$201,$A4)) -> 3 | J4: =IF($A4="","",I4*1000+H4*10+F4) -> 3056 | K4: =IF($A4="","",J4-ROW()/100000) -> 3056 | L4: =IF($A4="","",RANK(K4,$K$2:$K$18,0)) -> 1 | N4: =IF((ROW()-1)<=COUNTA(Equipos!$A$2:$A$18),ROW()-1,"") -> 3 | O4: =IFERROR(INDEX($A$2:$A$18,MATCH($N4,$L$2:$L$18,0)),"") -> MACULA DEL MAL | P4: =IFERROR(INDEX($B$2:$B$18,MATCH($N4,$L$2:$L$18,0)),"") -> 1 | Q4: =IFERROR(INDEX($C$2:$C$18,MATCH($N4,$L$2:$L$18,0)),"") -> 0 | R4: =IFERROR(INDEX($D$2:$D$18,MATCH($N4,$L$2:$L$18,0)),"") -> 1 | S4: =IFERROR(INDEX($E$2:$E$18,MATCH($N4,$L$2:$L$18,0)),"") -> 0 | T4: =IFERROR(INDEX($F$2:$F$18,MATCH($N4,$L$2:$L$18,0)),"") -> 4 | U4: =IFERROR(INDEX($G$2:$G$18,MATCH($N4,$L$2:$L$18,0)),"") -> 4 | V4: =IFERROR(INDEX($H$2:$H$18,MATCH($N4,$L$2:$L$18,0)),"") -> 0 | W4: =IFERROR(INDEX($I$2:$I$18,MATCH($N4,$L$2:$L$18,0)),"") -> 1
A5: =IF(Equipos!A5="","",Equipos!A5) -> LEONARD | B5: =IF($A5="","",COUNTIF(Detalle!$A$2:$A$201,$A5)) -> 1 | C5: =IF($A5="","",COUNTIFS(Detalle!$A$2:$A$201,$A5,Detalle!$D$2:$D$201,"G")) -> 1 | D5: =IF($A5="","",COUNTIFS(Detalle!$A$2:$A$201,$A5,Detalle!$D$2:$D$201,"E")) -> 0 | E5: =IF($A5="","",COUNTIFS(Detalle!$A$2:$A$201,$A5,Detalle!$D$2:$D$201,"P")) -> 0 | F5: =IF($A5="","",SUMIFS(Detalle!$B$2:$B$201,Detalle!$A$2:$A$201,$A5)) -> 5 | G5: =IF($A5="","",SUMIFS(Detalle!$C$2:$C$201,Detalle!$A$2:$A$201,$A5)) -> 2 | H5: =IF($A5="","",F5-G5) -> 3 | I5: =IF($A5="","",SUMIFS(Detalle!$E$2:$E$201,Detalle!$A$2:$A$201,$A5)) -> 3 | J5: =IF($A5="","",I5*1000+H5*10+F5) -> 3035 | K5: =IF($A5="","",J5-ROW()/100000) -> 3034.9999 | L5: =IF($A5="","",RANK(K5,$K$2:$K$18,0)) -> 2 | N5: =IF((ROW()-1)<=COUNTA(Equipos!$A$2:$A$18),ROW()-1,"") -> 4 | O5: =IFERROR(INDEX($A$2:$A$18,MATCH($N5,$L$2:$L$18,0)),"") -> MULTIAVISOS DE LA 12 | P5: =IFERROR(INDEX($B$2:$B$18,MATCH($N5,$L$2:$L$18,0)),"") -> 1 | Q5: =IFERROR(INDEX($C$2:$C$18,MATCH($N5,$L$2:$L$18,0)),"") -> 0 | R5: =IFERROR(INDEX($D$2:$D$18,MATCH($N5,$L$2:$L$18,0)),"") -> 1 | S5: =IFERROR(INDEX($E$2:$E$18,MATCH($N5,$L$2:$L$18,0)),"") -> 0 | T5: =IFERROR(INDEX($F$2:$F$18,MATCH($N5,$L$2:$L$18,0)),"") -> 4 | U5: =IFERROR(INDEX($G$2:$G$18,MATCH($N5,$L$2:$L$18,0)),"") -> 4 | V5: =IFERROR(INDEX($H$2:$H$18,MATCH($N5,$L$2:$L$18,0)),"") -> 0 | W5: =IFERROR(INDEX($I$2:$I$18,MATCH($N5,$L$2:$L$18,0)),"") -> 1
A6: =IF(Equipos!A6="","",Equipos!A6) -> MACULA DEL MAL | B6: =IF($A6="","",COUNTIF(Detalle!$A$2:$A$201,$A6)) -> 1 | C6: =IF($A6="","",COUNTIFS(Detalle!$A$2:$A$201,$A6,Detalle!$D$2:$D$201,"G")) -> 0 | D6: =IF($A6="","",COUNTIFS(Detalle!$A$2:$A$201,$A6,Detalle!$D$2:$D$201,"E")) -> 1 | E6: =IF($A6="","",COUNTIFS(Detalle!$A$2:$A$201,$A6,Detalle!$D$2:$D$201,"P")) -> 0 | F6: =IF($A6="","",SUMIFS(Detalle!$B$2:$B$201,Detalle!$A$2:$A$201,$A6)) -> 4 | G6: =IF($A6="","",SUMIFS(Detalle!$C$2:$C$201,Detalle!$A$2:$A$201,$A6)) -> 4 | H6: =IF($A6="","",F6-G6) -> 0 | I6: =IF($A6="","",SUMIFS(Detalle!$E$2:$E$201,Detalle!$A$2:$A$201,$A6)) -> 1 | J6: =IF($A6="","",I6*1000+H6*10+F6) -> 1004 | K6: =IF($A6="","",J6-ROW()/100000) -> 1003.9999 | L6: =IF($A6="","",RANK(K6,$K$2:$K$18,0)) -> 3 | N6: =IF((ROW()-1)<=COUNTA(Equipos!$A$2:$A$18),ROW()-1,"") -> 5 | O6: =IFERROR(INDEX($A$2:$A$18,MATCH($N6,$L$2:$L$18,0)),"") -> GRAFICAJAS | P6: =IFERROR(INDEX($B$2:$B$18,MATCH($N6,$L$2:$L$18,0)),"") -> 1 | Q6: =IFERROR(INDEX($C$2:$C$18,MATCH($N6,$L$2:$L$18,0)),"") -> 0 | R6: =IFERROR(INDEX($D$2:$D$18,MATCH($N6,$L$2:$L$18,0)),"") -> 0 | S6: =IFERROR(INDEX($E$2:$E$18,MATCH($N6,$L$2:$L$18,0)),"") -> 1 | T6: =IFERROR(INDEX($F$2:$F$18,MATCH($N6,$L$2:$L$18,0)),"") -> 2 | U6: =IFERROR(INDEX($G$2:$G$18,MATCH($N6,$L$2:$L$18,0)),"") -> 5 | V6: =IFERROR(INDEX($H$2:$H$18,MATCH($N6,$L$2:$L$18,0)),"") -> -3 | W6: =IFERROR(INDEX($I$2:$I$18,MATCH($N6,$L$2:$L$18,0)),"") -> 0
A7: =IF(Equipos!A7="","",Equipos!A7) -> MULTIAVISOS DE LA 12 | B7: =IF($A7="","",COUNTIF(Detalle!$A$2:$A$201,$A7)) -> 1 | C7: =IF($A7="","",COUNTIFS(Detalle!$A$2:$A$201,$A7,Detalle!$D$2:$D$201,"G")) -> 0 | D7: =IF($A7="","",COUNTIFS(Detalle!$A$2:$A$201,$A7,Detalle!$D$2:$D$201,"E")) -> 1 | E7: =IF($A7="","",COUNTIFS(Detalle!$A$2:$A$201,$A7,Detalle!$D$2:$D$201,"P")) -> 0 | F7: =IF($A7="","",SUMIFS(Detalle!$B$2:$B$201,Detalle!$A$2:$A$201,$A7)) -> 4 | G7: =IF($A7="","",SUMIFS(Detalle!$C$2:$C$201,Detalle!$A$2:$A$201,$A7)) -> 4 | H7: =IF($A7="","",F7-G7) -> 0 | I7: =IF($A7="","",SUMIFS(Detalle!$E$2:$E$201,Detalle!$A$2:$A$201,$A7)) -> 1 | J7: =IF($A7="","",I7*1000+H7*10+F7) -> 1004 | K7: =IF($A7="","",J7-ROW()/100000) -> 1003.9999 | L7: =IF($A7="","",RANK(K7,$K$2:$K$18,0)) -> 4 | N7: =IF((ROW()-1)<=COUNTA(Equipos!$A$2:$A$18),ROW()-1,"") -> 6 | O7: =IFERROR(INDEX($A$2:$A$18,MATCH($N7,$L$2:$L$18,0)),"") -> X-GRAPHICS | P7: =IFERROR(INDEX($B$2:$B$18,MATCH($N7,$L$2:$L$18,0)),"") -> 1 | Q7: =IFERROR(INDEX($C$2:$C$18,MATCH($N7,$L$2:$L$18,0)),"") -> 0 | R7: =IFERROR(INDEX($D$2:$D$18,MATCH($N7,$L$2:$L$18,0)),"") -> 0 | S7: =IFERROR(INDEX($E$2:$E$18,MATCH($N7,$L$2:$L$18,0)),"") -> 1 | T7: =IFERROR(INDEX($F$2:$F$18,MATCH($N7,$L$2:$L$18,0)),"") -> 1 | U7: =IFERROR(INDEX($G$2:$G$18,MATCH($N7,$L$2:$L$18,0)),"") -> 6 | V7: =IFERROR(INDEX($H$2:$H$18,MATCH($N7,$L$2:$L$18,0)),"") -> -5 | W7: =IFERROR(INDEX($I$2:$I$18,MATCH($N7,$L$2:$L$18,0)),"") -> 0
A8: =IF(Equipos!A8="","",Equipos!A8) | B8: =IF($A8="","",COUNTIF(Detalle!$A$2:$A$201,$A8)) | C8: =IF($A8="","",COUNTIFS(Detalle!$A$2:$A$201,$A8,Detalle!$D$2:$D$201,"G")) | D8: =IF($A8="","",COUNTIFS(Detalle!$A$2:$A$201,$A8,Detalle!$D$2:$D$201,"E")) | E8: =IF($A8="","",COUNTIFS(Detalle!$A$2:$A$201,$A8,Detalle!$D$2:$D$201,"P")) | F8: =IF($A8="","",SUMIFS(Detalle!$B$2:$B$201,Detalle!$A$2:$A$201,$A8)) | G8: =IF($A8="","",SUMIFS(Detalle!$C$2:$C$201,Detalle!$A$2:$A$201,$A8)) | H8: =IF($A8="","",F8-G8) | I8: =IF($A8="","",SUMIFS(Detalle!$E$2:$E$201,Detalle!$A$2:$A$201,$A8)) | J8: =IF($A8="","",I8*1000+H8*10+F8) | K8: =IF($A8="","",J8-ROW()/100000) | L8: =IF($A8="","",RANK(K8,$K$2:$K$18,0)) | N8: =IF((ROW()-1)<=COUNTA(Equipos!$A$2:$A$18),ROW()-1,"") | O8: =IFERROR(INDEX($A$2:$A$18,MATCH($N8,$L$2:$L$18,0)),"") | P8: =IFERROR(INDEX($B$2:$B$18,MATCH($N8,$L$2:$L$18,0)),"") | Q8: =IFERROR(INDEX($C$2:$C$18,MATCH($N8,$L$2:$L$18,0)),"") | R8: =IFERROR(INDEX($D$2:$D$18,MATCH($N8,$L$2:$L$18,0)),"") | S8: =IFERROR(INDEX($E$2:$E$18,MATCH($N8,$L$2:$L$18,0)),"") | T8: =IFERROR(INDEX($F$2:$F$18,MATCH($N8,$L$2:$L$18,0)),"") | U8: =IFERROR(INDEX($G$2:$G$18,MATCH($N8,$L$2:$L$18,0)),"") | V8: =IFERROR(INDEX($H$2:$H$18,MATCH($N8,$L$2:$L$18,0)),"") | W8: =IFERROR(INDEX($I$2:$I$18,MATCH($N8,$L$2:$L$18,0)),"")
A9: =IF(Equipos!A9="","",Equipos!A9) | B9: =IF($A9="","",COUNTIF(Detalle!$A$2:$A$201,$A9)) | C9: =IF($A9="","",COUNTIFS(Detalle!$A$2:$A$201,$A9,Detalle!$D$2:$D$201,"G")) | D9: =IF($A9="","",COUNTIFS(Detalle!$A$2:$A$201,$A9,Detalle!$D$2:$D$201,"E")) | E9: =IF($A9="","",COUNTIFS(Detalle!$A$2:$A$201,$A9,Detalle!$D$2:$D$201,"P")) | F9: =IF($A9="","",SUMIFS(Detalle!$B$2:$B$201,Detalle!$A$2:$A$201,$A9)) | G9: =IF($A9="","",SUMIFS(Detalle!$C$2:$C$201,Detalle!$A$2:$A$201,$A9)) | H9: =IF($A9="","",F9-G9) | I9: =IF($A9="","",SUMIFS(Detalle!$E$2:$E$201,Detalle!$A$2:$A$201,$A9)) | J9: =IF($A9="","",I9*1000+H9*10+F9) | K9: =IF($A9="","",J9-ROW()/100000) | L9: =IF($A9="","",RANK(K9,$K$2:$K$18,0)) | N9: =IF((ROW()-1)<=COUNTA(Equipos!$A$2:$A$18),ROW()-1,"") | O9: =IFERROR(INDEX($A$2:$A$18,MATCH($N9,$L$2:$L$18,0)),"") | P9: =IFERROR(INDEX($B$2:$B$18,MATCH($N9,$L$2:$L$18,0)),"") | Q9: =IFERROR(INDEX($C$2:$C$18,MATCH($N9,$L$2:$L$18,0)),"") | R9: =IFERROR(INDEX($D$2:$D$18,MATCH($N9,$L$2:$L$18,0)),"") | S9: =IFERROR(INDEX($E$2:$E$18,MATCH($N9,$L$2:$L$18,0)),"") | T9: =IFERROR(INDEX($F$2:$F$18,MATCH($N9,$L$2:$L$18,0)),"") | U9: =IFERROR(INDEX($G$2:$G$18,MATCH($N9,$L$2:$L$18,0)),"") | V9: =IFERROR(INDEX($H$2:$H$18,MATCH($N9,$L$2:$L$18,0)),"") | W9: =IFERROR(INDEX($I$2:$I$18,MATCH($N9,$L$2:$L$18,0)),"")
A10: =IF(Equipos!A10="","",Equipos!A10) | B10: =IF($A10="","",COUNTIF(Detalle!$A$2:$A$201,$A10)) | C10: =IF($A10="","",COUNTIFS(Detalle!$A$2:$A$201,$A10,Detalle!$D$2:$D$201,"G")) | D10: =IF($A10="","",COUNTIFS(Detalle!$A$2:$A$201,$A10,Detalle!$D$2:$D$201,"E")) | E10: =IF($A10="","",COUNTIFS(Detalle!$A$2:$A$201,$A10,Detalle!$D$2:$D$201,"P")) | F10: =IF($A10="","",SUMIFS(Detalle!$B$2:$B$201,Detalle!$A$2:$A$201,$A10)) | G10: =IF($A10="","",SUMIFS(Detalle!$C$2:$C$201,Detalle!$A$2:$A$201,$A10)) | H10: =IF($A10="","",F10-G10) | I10: =IF($A10="","",SUMIFS(Detalle!$E$2:$E$201,Detalle!$A$2:$A$201,$A10)) | J10: =IF($A10="","",I10*1000+H10*10+F10) | K10: =IF($A10="","",J10-ROW()/100000) | L10: =IF($A10="","",RANK(K10,$K$2:$K$18,0)) | N10: =IF((ROW()-1)<=COUNTA(Equipos!$A$2:$A$18),ROW()-1,"") | O10: =IFERROR(INDEX($A$2:$A$18,MATCH($N10,$L$2:$L$18,0)),"") | P10: =IFERROR(INDEX($B$2:$B$18,MATCH($N10,$L$2:$L$18,0)),"") | Q10: =IFERROR(INDEX($C$2:$C$18,MATCH($N10,$L$2:$L$18,0)),"") | R10: =IFERROR(INDEX($D$2:$D$18,MATCH($N10,$L$2:$L$18,0)),"") | S10: =IFERROR(INDEX($E$2:$E$18,MATCH($N10,$L$2:$L$18,0)),"") | T10: =IFERROR(INDEX($F$2:$F$18,MATCH($N10,$L$2:$L$18,0)),"") | U10: =IFERROR(INDEX($G$2:$G$18,MATCH($N10,$L$2:$L$18,0)),"") | V10: =IFERROR(INDEX($H$2:$H$18,MATCH($N10,$L$2:$L$18,0)),"") | W10: =IFERROR(INDEX($I$2:$I$18,MATCH($N10,$L$2:$L$18,0)),"")
A11: =IF(Equipos!A11="","",Equipos!A11) | B11: =IF($A11="","",COUNTIF(Detalle!$A$2:$A$201,$A11)) | C11: =IF($A11="","",COUNTIFS(Detalle!$A$2:$A$201,$A11,Detalle!$D$2:$D$201,"G")) | D11: =IF($A11="","",COUNTIFS(Detalle!$A$2:$A$201,$A11,Detalle!$D$2:$D$201,"E")) | E11: =IF($A11="","",COUNTIFS(Detalle!$A$2:$A$201,$A11,Detalle!$D$2:$D$201,"P")) | F11: =IF($A11="","",SUMIFS(Detalle!$B$2:$B$201,Detalle!$A$2:$A$201,$A11)) | G11: =IF($A11="","",SUMIFS(Detalle!$C$2:$C$201,Detalle!$A$2:$A$201,$A11)) | H11: =IF($A11="","",F11-G11) | I11: =IF($A11="","",SUMIFS(Detalle!$E$2:$E$201,Detalle!$A$2:$A$201,$A11)) | J11: =IF($A11="","",I11*1000+H11*10+F11) | K11: =IF($A11="","",J11-ROW()/100000) | L11: =IF($A11="","",RANK(K11,$K$2:$K$18,0)) | N11: =IF((ROW()-1)<=COUNTA(Equipos!$A$2:$A$18),ROW()-1,"") | O11: =IFERROR(INDEX($A$2:$A$18,MATCH($N11,$L$2:$L$18,0)),"") | P11: =IFERROR(INDEX($B$2:$B$18,MATCH($N11,$L$2:$L$18,0)),"") | Q11: =IFERROR(INDEX($C$2:$C$18,MATCH($N11,$L$2:$L$18,0)),"") | R11: =IFERROR(INDEX($D$2:$D$18,MATCH($N11,$L$2:$L$18,0)),"") | S11: =IFERROR(INDEX($E$2:$E$18,MATCH($N11,$L$2:$L$18,0)),"") | T11: =IFERROR(INDEX($F$2:$F$18,MATCH($N11,$L$2:$L$18,0)),"") | U11: =IFERROR(INDEX($G$2:$G$18,MATCH($N11,$L$2:$L$18,0)),"") | V11: =IFERROR(INDEX($H$2:$H$18,MATCH($N11,$L$2:$L$18,0)),"") | W11: =IFERROR(INDEX($I$2:$I$18,MATCH($N11,$L$2:$L$18,0)),"")
A12: =IF(Equipos!A12="","",Equipos!A12) | B12: =IF($A12="","",COUNTIF(Detalle!$A$2:$A$201,$A12)) | C12: =IF($A12="","",COUNTIFS(Detalle!$A$2:$A$201,$A12,Detalle!$D$2:$D$201,"G")) | D12: =IF($A12="","",COUNTIFS(Detalle!$A$2:$A$201,$A12,Detalle!$D$2:$D$201,"E")) | E12: =IF($A12="","",COUNTIFS(Detalle!$A$2:$A$201,$A12,Detalle!$D$2:$D$201,"P")) | F12: =IF($A12="","",SUMIFS(Detalle!$B$2:$B$201,Detalle!$A$2:$A$201,$A12)) | G12: =IF($A12="","",SUMIFS(Detalle!$C$2:$C$201,Detalle!$A$2:$A$201,$A12)) | H12: =IF($A12="","",F12-G12) | I12: =IF($A12="","",SUMIFS(Detalle!$E$2:$E$201,Detalle!$A$2:$A$201,$A12)) | J12: =IF($A12="","",I12*1000+H12*10+F12) | K12: =IF($A12="","",J12-ROW()/100000) | L12: =IF($A12="","",RANK(K12,$K$2:$K$18,0)) | N12: =IF((ROW()-1)<=COUNTA(Equipos!$A$2:$A$18),ROW()-1,"") | O12: =IFERROR(INDEX($A$2:$A$18,MATCH($N12,$L$2:$L$18,0)),"") | P12: =IFERROR(INDEX($B$2:$B$18,MATCH($N12,$L$2:$L$18,0)),"") | Q12: =IFERROR(INDEX($C$2:$C$18,MATCH($N12,$L$2:$L$18,0)),"") | R12: =IFERROR(INDEX($D$2:$D$18,MATCH($N12,$L$2:$L$18,0)),"") | S12: =IFERROR(INDEX($E$2:$E$18,MATCH($N12,$L$2:$L$18,0)),"") | T12: =IFERROR(INDEX($F$2:$F$18,MATCH($N12,$L$2:$L$18,0)),"") | U12: =IFERROR(INDEX($G$2:$G$18,MATCH($N12,$L$2:$L$18,0)),"") | V12: =IFERROR(INDEX($H$2:$H$18,MATCH($N12,$L$2:$L$18,0)),"") | W12: =IFERROR(INDEX($I$2:$I$18,MATCH($N12,$L$2:$L$18,0)),"")
A13: =IF(Equipos!A13="","",Equipos!A13) | B13: =IF($A13="","",COUNTIF(Detalle!$A$2:$A$201,$A13)) | C13: =IF($A13="","",COUNTIFS(Detalle!$A$2:$A$201,$A13,Detalle!$D$2:$D$201,"G")) | D13: =IF($A13="","",COUNTIFS(Detalle!$A$2:$A$201,$A13,Detalle!$D$2:$D$201,"E")) | E13: =IF($A13="","",COUNTIFS(Detalle!$A$2:$A$201,$A13,Detalle!$D$2:$D$201,"P")) | F13: =IF($A13="","",SUMIFS(Detalle!$B$2:$B$201,Detalle!$A$2:$A$201,$A13)) | G13: =IF($A13="","",SUMIFS(Detalle!$C$2:$C$201,Detalle!$A$2:$A$201,$A13)) | H13: =IF($A13="","",F13-G13) | I13: =IF($A13="","",SUMIFS(Detalle!$E$2:$E$201,Detalle!$A$2:$A$201,$A13)) | J13: =IF($A13="","",I13*1000+H13*10+F13) | K13: =IF($A13="","",J13-ROW()/100000) | L13: =IF($A13="","",RANK(K13,$K$2:$K$18,0)) | N13: =IF((ROW()-1)<=COUNTA(Equipos!$A$2:$A$18),ROW()-1,"") | O13: =IFERROR(INDEX($A$2:$A$18,MATCH($N13,$L$2:$L$18,0)),"") | P13: =IFERROR(INDEX($B$2:$B$18,MATCH($N13,$L$2:$L$18,0)),"") | Q13: =IFERROR(INDEX($C$2:$C$18,MATCH($N13,$L$2:$L$18,0)),"") | R13: =IFERROR(INDEX($D$2:$D$18,MATCH($N13,$L$2:$L$18,0)),"") | S13: =IFERROR(INDEX($E$2:$E$18,MATCH($N13,$L$2:$L$18,0)),"") | T13: =IFERROR(INDEX($F$2:$F$18,MATCH($N13,$L$2:$L$18,0)),"") | U13: =IFERROR(INDEX($G$2:$G$18,MATCH($N13,$L$2:$L$18,0)),"") | V13: =IFERROR(INDEX($H$2:$H$18,MATCH($N13,$L$2:$L$18,0)),"") | W13: =IFERROR(INDEX($I$2:$I$18,MATCH($N13,$L$2:$L$18,0)),"")
... A18: =IF(Equipos!A18="","",Equipos!A18) | B18: =IF($A18="","",COUNTIF(Detalle!$A$2:$A$201,$A18)) | C18: =IF($A18="","",COUNTIFS(Detalle!$A$2:$A$201,$A18,Detalle!$D$2:$D$201,"G")) | D18: =IF($A18="","",COUNTIFS(Detalle!$A$2:$A$201,$A18,Detalle!$D$2:$D$201,"E")) | E18: =IF($A18="","",COUNTIFS(Detalle!$A$2:$A$201,$A18,Detalle!$D$2:$D$201,"P")) | F18: =IF($A18="","",SUMIFS(Detalle!$B$2:$B$201,Detalle!$A$2:$A$201,$A18)) | G18: =IF($A18="","",SUMIFS(Detalle!$C$2:$C$201,Detalle!$A$2:$A$201,$A18)) | H18: =IF($A18="","",F18-G18) | I18: =IF($A18="","",SUMIFS(Detalle!$E$2:$E$201,Detalle!$A$2:$A$201,$A18)) | J18: =IF($A18="","",I18*1000+H18*10+F18) | K18: =IF($A18="","",J18-ROW()/100000) | L18: =IF($A18="","",RANK(K18,$K$2:$K$18,0)) | N18: =IF((ROW()-1)<=COUNTA(Equipos!$A$2:$A$18),ROW()-1,"") | O18: =IFERROR(INDEX($A$2:$A$18,MATCH($N18,$L$2:$L$18,0)),"") | P18: =IFERROR(INDEX($B$2:$B$18,MATCH($N18,$L$2:$L$18,0)),"") | Q18: =IFERROR(INDEX($C$2:$C$18,MATCH($N18,$L$2:$L$18,0)),"") | R18: =IFERROR(INDEX($D$2:$D$18,MATCH($N18,$L$2:$L$18,0)),"") | S18: =IFERROR(INDEX($E$2:$E$18,MATCH($N18,$L$2:$L$18,0)),"") | T18: =IFERROR(INDEX($F$2:$F$18,MATCH($N18,$L$2:$L$18,0)),"") | U18: =IFERROR(INDEX($G$2:$G$18,MATCH($N18,$L$2:$L$18,0)),"") | V18: =IFERROR(INDEX($H$2:$H$18,MATCH($N18,$L$2:$L$18,0)),"") | W18: =IFERROR(INDEX($I$2:$I$18,MATCH($N18,$L$2:$L$18,0)),"")
N20: Esta tabla se ordena sola. No uses Datos > Ordenar rango aquí — con fórmulas dentro, ordenar manualmente puede desordenar los datos.
